# tryブロックの中から呼び出した関数内で例外が発生した場合
try...catch 文を使った例外処理は、 try ブロック内に記述された文で例外がスローされた場合に例外をキャッチして処理を実行するものですが、 try 文の中から呼び出した関数の中で例外が発生した場合でも例外をキャッチすることができます。
ただ、コールバック関数を使用する場合には注意が必要です。

## tryブロックの中から呼び出した関数内で例外が発生した場合
try...catch 文の書式は次のようになっており、例外が発生する可能性がある文を try のあとのブロック内に記述しておく必要があります。

### try{
###   例外が発生する可能性がある文を記述
###   ・・・
### } catch(e) {
###   例外をキャッチしたときに実行される処理
###   ・・・
### }
それでは try ブロックの中で try...catch 文の外に記述された関数を呼びだし、その関数内で例外がスローされた場合はどうなるのでしょうか。

### function func(){
###   // ここで例外が発生
### }
### 
### try{
###   func();
### } catch(e) {
###   例外をキャッチしたときに実行される処理
###   ・・・
### }
このような場合でも try ブロック内で例外がスローされた場合と同じく例外をキャッチして catch のあとのブロック内の処理を事項します。

例外が発生する可能性のある関数を try ブロック内に記述するのではなく、関数を呼びだす文を try ブロックの中に記述しています。
呼びだした関数は try ブロック内には記述されていませんが、このようなケースであっても関数がスローした例外を関数の呼び出し側でキャッチして処理することができます。

最終的に呼び出された関数でスローされた例外は、呼び出し元を順にさかのぼっていき、いずれかのところで try...catch 文を使って例外をキャッチできれば例外に対する処理を行うことができます。

## 非同期処理のコールバック関数で例外が発生した場合
呼びだした関数内で発生した例外は、関数を呼びだした側でキャッチできるという点は先ほど解説しましたが、注意点もあります。
それは非同期処理を行うコールバック関数の中で発生した例外はキャッチすることができないという点です。

